Workbook

Sheet Modelo
A1: MODELO DE MÁRGENES — TIENDA ONLINE DE PERFUMES
A2: Proveedor: Star Company (Ciudad del Este, PY) · Precios de lista en USD · Costo de traída NO incluido (configurable abajo)
A4: SUPUESTOS (editar las celdas azules)
A5: Cotización USD → ARS | B5: 1300 | C5: Editar con el dólar real con el que se compra
A6: Costo de traída (%) | B6: 0 | C6: En 0 por ahora (no se considera). Cambiar cuando se defina
A7: Markup objetivo (x) | B7: 2.5 | C7: Multiplicador sobre el costo para el PVP sugerido
A9: Marca | B9: Producto | C9: ml | D9: Categoría | E9: Costo USD (lista) | F9: Costo ARS (c/ traída) | G9: PVP sugerido (ARS) | H9: Margen $ (ARS) | I9: Margen % | J9: Precio mercado AR (ref.) | K9: Comentario
A10: 12 Parfumeurs Français | B10: 12 PARFUMEURS FRANCAIS FONTAINEBLEAU EXDP 100ML UNISEX | C10: 100 | D10: Nicho | E10: 155 | F10: =E10*$B$5*(1+$B$6) -> 201500 | G10: =F10*$B$7 -> 503750 | H10: =G10-F10 -> 302250 | I10: =H10/G10 -> 0.6
A11: 12 Parfumeurs Français | B11: 12 PARFUMEURS FRANCAIS LUXEMBOURG EXDP 100ML UNISEX | C11: 100 | D11: Nicho | E11: 155 | F11: =E11*$B$5*(1+$B$6) -> 201500 | G11: =F11*$B$7 -> 503750 | H11: =G11-F11 -> 302250 | I11: =H11/G11 -> 0.6
A12: 12 Parfumeurs Français | B12: 12 PARFUMEURS FRANCAIS MADAME ROYALE EXDP 100ML UNISEX | C12: 100 | D12: Nicho | E12: 155 | F12: =E12*$B$5*(1+$B$6) -> 201500 | G12: =F12*$B$7 -> 503750 | H12: =G12-F12 -> 302250 | I12: =H12/G12 -> 0.6
A13: 12 Parfumeurs Français | B13: 12 PARFUMEURS FRANCAIS MALMAISON EXDP 100ML UNISEX | C13: 100 | D13: Nicho | E13: 155 | F13: =E13*$B$5*(1+$B$6) -> 201500 | G13: =F13*$B$7 -> 503750 | H13: =G13-F13 -> 302250 | I13: =H13/G13 -> 0.6
A14: 12 Parfumeurs Français | B14: 12 PARFUMEURS FRANCAIS PRAFRANCE EXDP 100ML UNISEX | C14: 100 | D14: Nicho | E14: 155 | F14: =E14*$B$5*(1+$B$6) -> 201500 | G14: =F14*$B$7 -> 503750 | H14: =G14-F14 -> 302250 | I14: =H14/G14 -> 0.6
A15: Afnan | B15: AFNAN 9AM DIVE EDP 100ML | C15: 100 | D15: Árabe | E15: 22.75 | F15: =E15*$B$5*(1+$B$6) -> 29575 | G15: =F15*$B$7 -> 73937.5 | H15: =G15-F15 -> 44362.5 | I15: =H15/G15 -> 0.6
A16: Afnan | B16: AFNAN 9AM DIVE EDP 150ML | C16: 150 | D16: Árabe | E16: 31 | F16: =E16*$B$5*(1+$B$6) -> 40300 | G16: =F16*$B$7 -> 100750 | H16: =G16-F16 -> 60450 | I16: =H16/G16 -> 0.6
A17: Afnan | B17: AFNAN 9PM (BLACK) EDP 150ML MASC | C17: 150 | D17: Árabe | E17: 31 | F17: =E17*$B$5*(1+$B$6) -> 40300 | G17: =F17*$B$7 -> 100750 | H17: =G17-F17 -> 60450 | I17: =H17/G17 -> 0.6
A18: Afnan | B18: AFNAN 9PM FEMME (PURPLE) EDP 100ML FEM | C18: 100 | D18: Árabe | E18: 22.25 | F18: =E18*$B$5*(1+$B$6) -> 28925 | G18: =F18*$B$7 -> 72312.5 | H18: =G18-F18 -> 43387.5 | I18: =H18/G18 -> 0.6
A19: Afnan | B19: AFNAN HISTORIC OLMEDA EDP 100ML | C19: 100 | D19: Árabe | E19: 23.75 | F19: =E19*$B$5*(1+$B$6) -> 30875 | G19: =F19*$B$7 -> 77187.5 | H19: =G19-F19 -> 46312.5 | I19: =H19/G19 -> 0.6
A20: Afnan | B20: AFNAN HISTORIC SAHARA EXTRAIT DE PARFUM 100ML | C20: 100 | D20: Árabe | E20: 28.5 | F20: =E20*$B$5*(1+$B$6) -> 37050 | G20: =F20*$B$7 -> 92625 | H20: =G20-F20 -> 55575 | I20: =H20/G20 -> 0.6
A21: Afnan | B21: AFNAN KIAANA ANGEL EDP 100ML FEMININO | C21: 100 | D21: Árabe | E21: 23.5 | F21: =E21*$B$5*(1+$B$6) -> 30550 | G21: =F21*$B$7 -> 76375 | H21: =G21-F21 -> 45825 | I21: =H21/G21 -> 0.6
... A37: Al Haramain | B37: AL HARAMAIN AMBER OUD ULTRA VIOLET EDP 120ML | C37: 120 | D37: Árabe | E37: 44 | F37: =E37*$B$5*(1+$B$6) -> 57200 | G37: =F37*$B$7 -> 143000 | H37: =G37-F37 -> 85800 | I37: =H37/G37 -> 0.6
A38: Al Haramain | B38: AL HARAMAIN AMBER OUD ULTRA VIOLET PERFUMERY GIFT SET WITH BODYMIST (7 | D38: Árabe | E38: 65 | F38: =E38*$B$5*(1+$B$6) -> 84500 | G38: =F38*$B$7 -> 211250 | H38: =G38-F38 -> 126750 | I38: =H38/G38 -> 0.6
A39: Al Haramain | B39: AL HARAMAIN AMBER OUD WHITE EDP 100ML | C39: 100 | D39: Árabe | E39: 31 | F39: =E39*$B$5*(1+$B$6) -> 40300 | G39: =F39*$B$7 -> 100750 | H39: =G39-F39 -> 60450 | I39: =H39/G39 -> 0.6
A40: Al Haramain | B40: AL HARAMAIN AVALON EDP 100ML | C40: 100 | D40: Árabe | E40: 28 | F40: =E40*$B$5*(1+$B$6) -> 36400 | G40: =F40*$B$7 -> 91000 | H40: =G40-F40 -> 54600 | I40: =H40/G40 -> 0.6
A41: Al Haramain | B41: AL HARAMAIN AZURE EDP 100ML | C41: 100 | D41: Árabe | E41: 28 | F41: =E41*$B$5*(1+$B$6) -> 36400 | G41: =F41*$B$7 -> 91000 | H41: =G41-F41 -> 54600 | I41: =H41/G41 -> 0.6
A42: Al Haramain | B42: AL HARAMAIN AZURE EDP 30ML | C42: 30 | D42: Árabe | E42: 11 | F42: =E42*$B$5*(1+$B$6) -> 14300 | G42: =F42*$B$7 -> 35750 | H42: =G42-F42 -> 21450 | I42: =H42/G42 -> 0.6
A43: Al Haramain | B43: AL HARAMAIN CONCEPTION EDP 100ML | C43: 100 | D43: Árabe | E43: 28 | F43: =E43*$B$5*(1+$B$6) -> 36400 | G43: =F43*$B$7 -> 91000 | H43: =G43-F43 -> 54600 | I43: =H43/G43 -> 0.6
A44: Al Haramain | B44: AL HARAMAIN CONCEPTION EDP 30ML | C44: 30 | D44: Árabe | E44: 11 | F44: =E44*$B$5*(1+$B$6) -> 14300 | G44: =F44*$B$7 -> 35750 | H44: =G44-F44 -> 21450 | I44: =H44/G44 -> 0.6
A45: Al Haramain | B45: AL HARAMAIN FLORAL FAIR EDP 100ML | C45: 100 | D45: Árabe | E45: 25 | F45: =E45*$B$5*(1+$B$6) -> 32500 | G45: =F45*$B$7 -> 81250 | H45: =G45-F45 -> 48750 | I45: =H45/G45 -> 0.6
A46: Al Haramain | B46: AL HARAMAIN FREYA EDP 100ML | C46: 100 | D46: Árabe | E46: 27 | F46: =E46*$B$5*(1+$B$6) -> 35100 | G46: =F46*$B$7 -> 87750 | H46: =G46-F46 -> 52650 | I46: =H46/G46 -> 0.6
A47: Al Haramain | B47: AL HARAMAIN FREYA EDP 30ML | C47: 30 | D47: Árabe | E47: 11 | F47: =E47*$B$5*(1+$B$6) -> 14300 | G47: =F47*$B$7 -> 35750 | H47: =G47-F47 -> 21450 | I47: =H47/G47 -> 0.6
A48: Al Haramain | B48: AL HARAMAIN GOLD CRYSTAL OUDH EXTRAIT DE PARFUM 100ML | C48: 100 | D48: Árabe | E48: 28.5 | F48: =E48*$B$5*(1+$B$6) -> 37050 | G48: =F48*$B$7 -> 92625 | H48: =G48-F48 -> 55575 | I48: =H48/G48 -> 0.6
A49: Al Haramain | B49: AL HARAMAIN GOLD CRYSTAL SAPHIRE 100ML | C49: 100 | D49: Árabe | E49: 28.5 | F49: =E49*$B$5*(1+$B$6) -> 37050 | G49: =F49*$B$7 -> 92625 | H49: =G49-F49 -> 55575 | I49: =H49/G49 -> 0.6
A50: Al Haramain | B50: AL HARAMAIN GREEN DUBAI EXTRAIT DE PARFUM 100ML | C50: 100 | D50: Árabe | E50: 25 | F50: =E50*$B$5*(1+$B$6) -> 32500 | G50: =F50*$B$7 -> 81250 | H50: =G50-F50 -> 48750 | I50: =H50/G50 -> 0.6
... A75: Al Haramain | B75: AL HARAMAIN SHEIKH MAJESTIC EXTRAIT DE PARFUM 100ML | C75: 100 | D75: Árabe | E75: 130 | F75: =E75*$B$5*(1+$B$6) -> 169000 | G75: =F75*$B$7 -> 422500 | H75: =G75-F75 -> 253500 | I75: =H75/G75 -> 0.6
A76: Al Haramain | B76: AL HARAMAIN SHEIKH PRESTIGE TRAVEL PACK WITH TUBE COVER + 4 TUBE BLACK | D76: Árabe | E76: 65 | F76: =E76*$B$5*(1+$B$6) -> 84500 | G76: =F76*$B$7 -> 211250 | H76: =G76-F76 -> 126750 | I76: =H76/G76 -> 0.6
A77: Al Haramain | B77: AL HARAMAIN SHEIKH PRESTIGE TRAVEL PACK WITH TUBE COVER + 4 TUBE BLUE | D77: Árabe | E77: 65 | F77: =E77*$B$5*(1+$B$6) -> 84500 | G77: =F77*$B$7 -> 211250 | H77: =G77-F77 -> 126750 | I77: =H77/G77 -> 0.6
A78: Al Haramain | B78: AL HARAMAIN SHEIKH PRESTIGE TRAVEL PACK WITH TUBE COVER + 4 TUBE GREEN | D78: Árabe | E78: 65 | F78: =E78*$B$5*(1+$B$6) -> 84500 | G78: =F78*$B$7 -> 211250 | H78: =G78-F78 -> 126750 | I78: =H78/G78 -> 0.6
A79: Al Haramain | B79: AL HARAMAIN SHEIKH PRESTIGE TRAVEL PACK WITH TUBE COVER + 4 TUBE RED | D79: Árabe | E79: 65 | F79: =E79*$B$5*(1+$B$6) -> 84500 | G79: =F79*$B$7 -> 211250 | H79: =G79-F79 -> 126750 | I79: =H79/G79 -> 0.6
A80: Al Haramain | B80: AL HARAMAIN SHEIKH ROYAL EXTRAIT DE PARFUM 100ML | C80: 100 | D80: Árabe | E80: 130 | F80: =E80*$B$5*(1+$B$6) -> 169000 | G80: =F80*$B$7 -> 422500 | H80: =G80-F80 -> 253500 | I80: =H80/G80 -> 0.6
A81: Al Haramain | B81: AL HARAMAIN SHEIKH WARRIOR EXTRAIT DE PARFUM 100ML | C81: 100 | D81: Árabe | E81: 130 | F81: =E81*$B$5*(1+$B$6) -> 169000 | G81: =F81*$B$7 -> 422500 | H81: =G81-F81 -> 253500 | I81: =H81/G81 -> 0.6
...

Sheet Resumen por marca
A1: Marca | B1: # productos | C1: Costo USD mín | D1: Costo USD máx | E1: Costo USD promedio | F1: Margen % promedio
A2: Lattafa | B2: =COUNTIF(Modelo!$A$10:$A$1922,$A2) -> 151 | C2: =MINIFS(Modelo!$E$10:$E$1922,Modelo!$A$10:$A$1922,$A2) -> 2.75 | D2: =MAXIFS(Modelo!$E$10:$E$1922,Modelo!$A$10:$A$1922,$A2) -> 43 | E2: =AVERAGEIF(Modelo!$A$10:$A$1922,$A2,Modelo!$E$10:$E$1922) -> 17.512517 | F2: =AVERAGEIF(Modelo!$A$10:$A$1922,$A2,Modelo!$I$10:$I$1922) -> 0.6
A3: Maison Alhambra | B3: =COUNTIF(Modelo!$A$10:$A$1922,$A3) -> 127 | C3: =MINIFS(Modelo!$E$10:$E$1922,Modelo!$A$10:$A$1922,$A3) -> 2.7 | D3: =MAXIFS(Modelo!$E$10:$E$1922,Modelo!$A$10:$A$1922,$A3) -> 24 | E3: =AVERAGEIF(Modelo!$A$10:$A$1922,$A3,Modelo!$E$10:$E$1922) -> 10.33315 | F3: =AVERAGEIF(Modelo!$A$10:$A$1922,$A3,Modelo!$I$10:$I$1922) -> 0.6
A4: Carolina Herrera | B4: =COUNTIF(Modelo!$A$10:$A$1922,$A4) -> 83 | C4: =MINIFS(Modelo!$E$10:$E$1922,Modelo!$A$10:$A$1922,$A4) -> 41 | D4: =MAXIFS(Modelo!$E$10:$E$1922,Modelo!$A$10:$A$1922,$A4) -> 98 | E4: =AVERAGEIF(Modelo!$A$10:$A$1922,$A4,Modelo!$E$10:$E$1922) -> 65.699398 | F4: =AVERAGEIF(Modelo!$A$10:$A$1922,$A4,Modelo!$I$10:$I$1922) -> 0.6
A5: Paco Rabanne | B5: =COUNTIF(Modelo!$A$10:$A$1922,$A5) -> 61 | C5: =MINIFS(Modelo!$E$10:$E$1922,Modelo!$A$10:$A$1922,$A5) -> 28 | D5: =MAXIFS(Modelo!$E$10:$E$1922,Modelo!$A$10:$A$1922,$A5) -> 115 | E5: =AVERAGEIF(Modelo!$A$10:$A$1922,$A5,Modelo!$E$10:$E$1922) -> 67.024426 | F5: =AVERAGEIF(Modelo!$A$10:$A$1922,$A5,Modelo!$I$10:$I$1922) -> 0.6
A6: Al Haramain | B6: =COUNTIF(Modelo!$A$10:$A$1922,$A6) -> 57 | C6: =MINIFS(Modelo!$E$10:$E$1922,Modelo!$A$10:$A$1922,$A6) -> 11 | D6: =MAXIFS(Modelo!$E$10:$E$1922,Modelo!$A$10:$A$1922,$A6) -> 130 | E6: =AVERAGEIF(Modelo!$A$10:$A$1922,$A6,Modelo!$E$10:$E$1922) -> 43.631404 | F6: =AVERAGEIF(Modelo!$A$10:$A$1922,$A6,Modelo!$I$10:$I$1922) -> 0.6
A7: Chanel | B7: =COUNTIF(Modelo!$A$10:$A$1922,$A7) -> 44 | C7: =MINIFS(Modelo!$E$10:$E$1922,Modelo!$A$10:$A$1922,$A7) -> 82 | D7: =MAXIFS(Modelo!$E$10:$E$1922,Modelo!$A$10:$A$1922,$A7) -> 265 | E7: =AVERAGEIF(Modelo!$A$10:$A$1922,$A7,Modelo!$E$10:$E$1922) -> 135.96591 | F7: =AVERAGEIF(Modelo!$A$10:$A$1922,$A7,Modelo!$I$10:$I$1922) -> 0.6
A8: Armaf | B8: =COUNTIF(Modelo!$A$10:$A$1922,$A8) -> 43 | C8: =MINIFS(Modelo!$E$10:$E$1922,Modelo!$A$10:$A$1922,$A8) -> 2.75 | D8: =MAXIFS(Modelo!$E$10:$E$1922,Modelo!$A$10:$A$1922,$A8) -> 50 | E8: =AVERAGEIF(Modelo!$A$10:$A$1922,$A8,Modelo!$E$10:$E$1922) -> 21.42093 | F8: =AVERAGEIF(Modelo!$A$10:$A$1922,$A8,Modelo!$I$10:$I$1922) -> 0.6
A9: Dolce & Gabbana | B9: =COUNTIF(Modelo!$A$10:$A$1922,$A9) -> 43 | C9: =MINIFS(Modelo!$E$10:$E$1922,Modelo!$A$10:$A$1922,$A9) -> 38 | D9: =MAXIFS(Modelo!$E$10:$E$1922,Modelo!$A$10:$A$1922,$A9) -> 95 | E9: =AVERAGEIF(Modelo!$A$10:$A$1922,$A9,Modelo!$E$10:$E$1922) -> 58.730233 | F9: =AVERAGEIF(Modelo!$A$10:$A$1922,$A9,Modelo!$I$10:$I$1922) -> 0.6
A10: Giorgio Armani | B10: =COUNTIF(Modelo!$A$10:$A$1922,$A10) -> 43 | C10: =MINIFS(Modelo!$E$10:$E$1922,Modelo!$A$10:$A$1922,$A10) -> 18 | D10: =MAXIFS(Modelo!$E$10:$E$1922,Modelo!$A$10:$A$1922,$A10) -> 330 | E10: =AVERAGEIF(Modelo!$A$10:$A$1922,$A10,Modelo!$E$10:$E$1922) -> 83.24186 | F10: =AVERAGEIF(Modelo!$A$10:$A$1922,$A10,Modelo!$I$10:$I$1922) -> 0.6
A11: Creed | B11: =COUNTIF(Modelo!$A$10:$A$1922,$A11) -> 41 | C11: =MINIFS(Modelo!$E$10:$E$1922,Modelo!$A$10:$A$1922,$A11) -> 195 | D11: =MAXIFS(Modelo!$E$10:$E$1922,Modelo!$A$10:$A$1922,$A11) -> 525 | E11: =AVERAGEIF(Modelo!$A$10:$A$1922,$A11,Modelo!$E$10:$E$1922) -> 275.90244 | F11: =AVERAGEIF(Modelo!$A$10:$A$1922,$A11,Modelo!$I$10:$I$1922) -> 0.6
A12: Jean Paul Gaultier | B12: =COUNTIF(Modelo!$A$10:$A$1922,$A12) -> 40 | C12: =MINIFS(Modelo!$E$10:$E$1922,Modelo!$A$10:$A$1922,$A12) -> 44 | D12: =MAXIFS(Modelo!$E$10:$E$1922,Modelo!$A$10:$A$1922,$A12) -> 115 | E12: =AVERAGEIF(Modelo!$A$10:$A$1922,$A12,Modelo!$E$10:$E$1922) -> 78.41 | F12: =AVERAGEIF(Modelo!$A$10:$A$1922,$A12,Modelo!$I$10:$I$1922) -> 0.6
A13: Givenchy | B13: =COUNTIF(Modelo!$A$10:$A$1922,$A13) -> 39 | C13: =MINIFS(Modelo!$E$10:$E$1922,Modelo!$A$10:$A$1922,$A13) -> 36 | D13: =MAXIFS(Modelo!$E$10:$E$1922,Modelo!$A$10:$A$1922,$A13) -> 110 | E13: =AVERAGEIF(Modelo!$A$10:$A$1922,$A13,Modelo!$E$10:$E$1922) -> 70.798718 | F13: =AVERAGEIF(Modelo!$A$10:$A$1922,$A13,Modelo!$I$10:$I$1922) -> 0.6
... A139: Tubbees | B139: =COUNTIF(Modelo!$A$10:$A$1922,$A139) -> 1 | C139: =MINIFS(Modelo!$E$10:$E$1922,Modelo!$A$10:$A$1922,$A139) -> 7.25 | D139: =MAXIFS(Modelo!$E$10:$E$1922,Modelo!$A$10:$A$1922,$A139) -> 7.25 | E139: =AVERAGEIF(Modelo!$A$10:$A$1922,$A139,Modelo!$E$10:$E$1922) -> 7.25 | F139: =AVERAGEIF(Modelo!$A$10:$A$1922,$A139,Modelo!$I$10:$I$1922) -> 0.6
A140: (TODAS LAS MARCAS) | B140: =SUM(B2:B139) -> 1913 | C140: =MIN(Modelo!$E$10:$E$1922) -> 2.7 | D140: =MAX(Modelo!$E$10:$E$1922) -> 525 | E140: =AVERAGE(Modelo!$E$10:$E$1922) -> 74.243236 | F140: =AVERAGE(Modelo!$I$10:$I$1922) -> 0.6

Sheet Notas
A1: NOTAS Y METODOLOGÍA
A3: Cómo usar este modelo:
A4: 1. Cargá la cotización real del dólar con el que compran (celda B5). Es el dato que más mueve los márgenes.
A5: 2. El 'Costo de traída %' (B6) está en 0 por ahora. Cuando definan el costo/riesgo de traer la mercadería, lo ponen ahí y todo se recalcula.
A6: 3. El 'Markup objetivo' (B7) define el PVP sugerido (PVP = costo x markup). Ajustalo según la categoría o editá el PVP fila por fila.
A7: 4. La columna 'Precio mercado AR' es referencia para chequear que el PVP sugerido sea competitivo (no es un cálculo).
A9: Origen de los datos:
A10: - Costos USD: precios de lista del sitio del proveedor Star Company (base.fluxoigm.com / starcompany-py.com), categoría Perfumes, junio 2026.
A11: - Precios de mercado AR: búsquedas en Mercado Libre y perfumerías online argentinas, junio 2026. Son rangos orientativos, no precios fijos.
A13: Limitaciones a tener en cuenta:
A14: - Las páginas del proveedor por marca no exponen precio público; los costos cargados salen del listado general y de carruseles de productos. Faltan SKUs (ej. Lattafa Yara/Khamrah) cuyo precio no se pudo leer todavía.
A15: - Para ampliar: si el proveedor te pasa una lista (CSV/planilla) o pantallazos por marca, se agregan filas y el modelo escala solo.
... A18: - Si obtienen rebajas por mayorista, actualizar la columna 'Costo USD' (azul) y los márgenes se recalculan.
